#VRML_SIM R2023b utf8

EXTERNPROTO "webots://projects/objects/backgrounds/protos/TexturedBackgroundLight.proto"
EXTERNPROTO "webots://projects/objects/backgrounds/protos/TexturedBackground.proto"
EXTERNPROTO "webots://projects/objects/floors/protos/Floor.proto"

WorldInfo {
  basicTimeStep 1
  FPS 30
  contactProperties [
    ContactProperties {
      coulombFriction [
        0.4
      ]
    }
  ]
}
Viewpoint {
  orientation 0.14546064017141774 0.06068217737989535 -0.9875013293709312 2.36004738102523
  position 2.2194022663318393 2.1467108637510295 1.5000363246340602
  follow "T1_release"
}
TexturedBackground {
  texture "empty_office"
}
TexturedBackgroundLight {
}
Floor {
  size 200 200
  tileSize 1 1
}
Robot {
  translation 0.007113312760517139 0.0007461850468461023 0.6524744793109749
  rotation -0.009350949686471701 -0.8953784812690506 -0.4452077436661331 0.023382995035227026
  children [
    Accelerometer {
      name "torso accelerometer"
    }
    GPS {
      name "torso gps"
    }
    Gyro {
      name "torso gyro"
    }
    InertialUnit {
      name "torso inertial unit"
    }
    Shape {
      appearance DEF Trunk_material PBRAppearance {
        baseColor 0.76 0.76 0.76
        roughness 1
        metalness 0
      }
      geometry DEF Trunk Mesh {
        url [
          "./T1_release_meshes/Trunk.STL"
        ]
      }
    }
    HingeJoint {
      jointParameters HingeJointParameters {
        position 7.867003368317663e-06
        axis 0 0 1
        anchor 0.0625 0 0.243
      }
      device [
        RotationalMotor {
          name "AAHead_yaw"
          maxTorque 10000
        }
        PositionSensor {
          name "AAHead_yaw_sensor"
        }
      ]
      endPoint Solid {
        translation 0.0625 0 0.243
        rotation 0 0 1 7.867022857576042e-06
        children [
          Shape {
            appearance DEF H1_material PBRAppearance {
              baseColor 0.4 0.4 0.4
              roughness 1
              metalness 0
            }
            geometry DEF H1 Mesh {
              url [
                "./T1_release_meshes/H1.STL"
              ]
            }
          }
          HingeJoint {
            jointParameters HingeJointParameters {
              position 0.009063125084966787
              axis 0 1 0
              anchor 0 0 0.06185
            }
            device [
              RotationalMotor {
                name "Head_pitch"
                maxTorque 10000
              }
              PositionSensor {
                name "Head_pitch_sensor"
              }
            ]
            endPoint DEF H2 Solid {
              translation 0 0 0.06185
              rotation 0 1 0 0.009063125084964317
              children [
                Shape {
                  appearance DEF H2_material PBRAppearance {
                    baseColor 0.4 0.4 0.4
                    roughness 1
                    metalness 0
                  }
                  geometry DEF H2 Mesh {
                    url [
                      "./T1_release_meshes/H2.STL"
                    ]
                  }
                }

              ]
              name "H2"
              boundingObject USE H2
              physics Physics {
                density -1
                mass 0.631019
                centerOfMass [
                  0.007802 0.001262 0.098631
                ]
                inertiaMatrix [
                  0.002025 0.00192 0.001739
                  -2.5e-05 4.6e-05 3.6e-05
                ]
              }
            }
          }
        ]
        name "H1"
        boundingObject USE H1
        physics Physics {
          density -1
          mass 0.44391
          centerOfMass [
            -0.000508 -0.001403 0.057432
          ]
          inertiaMatrix [
            0.000224 0.000241 0.00015
            3e-06 1e-06 -2e-06
          ]
        }
      }
    }
    HingeJoint {
      jointParameters HingeJointParameters {
        position 0.24123414426660947
        axis 0 1 0
        anchor 0.0575 0.1063 0.219
      }
      device [
        RotationalMotor {
          name "Left_Shoulder_Pitch"
          maxTorque 10000
        }
        PositionSensor {
          name "Left_Shoulder_Pitch_sensor"
        }
      ]
      endPoint Solid {
        translation 0.0575 0.1063 0.219
        rotation 0 1 0 0.24211514426637507
        children [
          Shape {
            appearance DEF AL1_material PBRAppearance {
              baseColor 0.76 0.76 0.76
              roughness 1
              metalness 0
            }
            geometry DEF AL1 Mesh {
              url [
                "./T1_release_meshes/AL1.STL"
              ]
            }
          }
          HingeJoint {
            jointParameters HingeJointParameters {
              position -1.4065962321111405
              anchor 0 0.047 0
            }
            device [
              RotationalMotor {
                name "Left_Shoulder_Roll"
                maxTorque 10000
              }
              PositionSensor {
                name "Left_Shoulder_Roll_sensor"
              }
            ]
            endPoint Solid {
              translation 0 0.047 0
              rotation -1 0 0 1.4065962321111405
              children [
                Shape {
                  appearance DEF AL2_material PBRAppearance {
                    baseColor 0.4 0.4 0.4
                    roughness 1
                    metalness 0
                  }
                  geometry DEF AL2 Mesh {
                    url [
                      "./T1_release_meshes/AL2.STL"
                    ]
                  }
                }
                HingeJoint {
                  jointParameters HingeJointParameters {
                    position 0.0008142467254101609
                    axis 0 1 0
                    anchor 0.00025 0.0605 0
                  }
                  device [
                    RotationalMotor {
                      name "Left_Elbow_Pitch"
                      maxTorque 10000
                    }
                    PositionSensor {
                      name "Left_Elbow_Pitch_sensor"
                    }
                  ]
                  endPoint Solid {
                    translation 0.00025 0.0605 0
                    rotation 0 1 0 0.0008142467254349899
                    children [
                      Shape {
                        appearance DEF AL3_material PBRAppearance {
                          baseColor 0.4 0.4 0.4
                          roughness 1
                          metalness 0
                        }
                        geometry DEF AL3 Mesh {
                          url [
                            "./T1_release_meshes/AL3.STL"
                          ]
                        }
                      }
                      HingeJoint {
                        jointParameters HingeJointParameters {
                          position -0.4952226673813227
                          axis 0 0 1
                          anchor 0 0.1471 0
                        }
                        device [
                          RotationalMotor {
                            name "Left_Elbow_Yaw"
                            maxTorque 10000
                          }
                          PositionSensor {
                            name "Left_Elbow_Yaw_sensor"
                          }
                        ]
                        endPoint Solid {
                          translation 0 0.1471 0
                          rotation 0 0 -1 0.4952226673813224
                          children [
                            Shape {
                              appearance DEF left_hand_link_material PBRAppearance {
                                baseColor 0.4 0.4 0.4
                                roughness 1
                                metalness 0
                              }
                              geometry DEF left_hand_link Mesh {
                                url [
                                  "./T1_release_meshes/left_hand_link.STL"
                                ]
                              }
                            }
                          ]
                          name "left_hand_link"
                          boundingObject USE left_hand_link
                          physics Physics {
                            density -1
                            mass 0.327214
                            centerOfMass [
                              -0.000108 0.109573 0.000591
                            ]
                            inertiaMatrix [
                              0.008159 0.000215 0.008131
                              -3e-06 0 1.7e-05
                            ]
                          }
                        }
                      }
                    ]
                    name "AL3"
                    boundingObject USE AL3
                    physics Physics {
                      density -1
                      mass 1.02
                      centerOfMass [
                        0 0.085353 -9.9e-05
                      ]
                      inertiaMatrix [
                        0.012869 0.000621 0.012798
                        0 0 -2.4e-05
                      ]
                    }
                  }
                }
              ]
              name "AL2"
              boundingObject USE AL2
              physics Physics {
                density -1
                mass 0.16
                centerOfMass [
                  0.003862 0.037976 0
                ]
                inertiaMatrix [
                  0.000345 0.000177 0.000401
                  8e-06 0 0
                ]
              }
            }
          }
        ]
        name "AL1"
        boundingObject USE AL1
        physics Physics {
          density -1
          mass 0.53
          centerOfMass [
            -0.000677 0.044974 0
          ]
          inertiaMatrix [
            0.001293 0.000293 0.001367
            -1.7e-05 0 0
          ]
        }
      }
    }
    HingeJoint {
      jointParameters HingeJointParameters {
        position 0.24125968159117467
        axis 0 1 0
        anchor 0.0575 -0.1063 0.219
      }
      device [
        RotationalMotor {
          name "Right_Shoulder_Pitch"
          maxTorque 10000
        }
        PositionSensor {
          name "Right_Shoulder_Pitch_sensor"
        }
      ]
      endPoint Solid {
        translation 0.0575 -0.1063 0.219
        rotation 0 1 0 0.24214068159093827
        children [
          Shape {
            appearance DEF AR1_material PBRAppearance {
              baseColor 0.76 0.76 0.76
              roughness 1
              metalness 0
            }
            geometry DEF AR1 Mesh {
              url [
                "./T1_release_meshes/AR1.STL"
              ]
            }
          }
          HingeJoint {
            jointParameters HingeJointParameters {
              position 1.406631010100869
              anchor 0 -0.047 0
            }
            device [
              RotationalMotor {
                name "Right_Shoulder_Roll"
                maxTorque 10000
              }
              PositionSensor {
                name "Right_Shoulder_Roll_sensor"
              }
            ]
            endPoint Solid {
              translation 0 -0.047 0
              rotation 1 0 0 1.406631010100869
              children [
                Shape {
                  appearance DEF AR2_material PBRAppearance {
                    baseColor 0.4 0.4 0.4
                    roughness 1
                    metalness 0
                  }
                  geometry DEF AR2 Mesh {
                    url [
                      "./T1_release_meshes/AR2.STL"
                    ]
                  }
                }
                HingeJoint {
                  jointParameters HingeJointParameters {
                    position 0.0008211725882565729
                    axis 0 1 0
                    anchor 0.00025 -0.0605 0
                  }
                  device [
                    RotationalMotor {
                      name "Right_Elbow_Pitch"
                      maxTorque 10000
                    }
                    PositionSensor {
                      name "Right_Elbow_Pitch_sensor"
                    }
                  ]
                  endPoint Solid {
                    translation 0.00025 -0.0605 0
                    rotation 0 1 0 0.0008211725884401372
                    children [
                      Shape {
                        appearance DEF AR3_material PBRAppearance {
                          baseColor 0.4 0.4 0.4
                          roughness 1
                          metalness 0
                        }
                        geometry DEF AR3 Mesh {
                          url [
                            "./T1_release_meshes/AR3.STL"
                          ]
                        }
                      }
                      HingeJoint {
                        jointParameters HingeJointParameters {
                          position 0.4952195542063547
                          axis 0 0 1
                          anchor 0 -0.1471 0
                        }
                        device [
                          RotationalMotor {
                            name "Right_Elbow_Yaw"
                            maxTorque 10000
                          }
                          PositionSensor {
                            name "Right_Elbow_Yaw_sensor"
                          }
                        ]
                        endPoint Solid {
                          translation 0 -0.1471 0
                          rotation 0 0 1 0.49521955420635483
                          children [
                            Shape {
                              appearance DEF right_hand_link_material PBRAppearance {
                                baseColor 0.4 0.4 0.4
                                roughness 1
                                metalness 0
                              }
                              geometry DEF right_hand_link Mesh {
                                url [
                                  "./T1_release_meshes/right_hand_link.STL"
                                ]
                              }
                            }
                          ]
                          name "right_hand_link"
                          boundingObject USE right_hand_link
                          physics Physics {
                            density -1
                            mass 0.327214
                            centerOfMass [
                              -0.000108 -0.109573 0.000591
                            ]
                            inertiaMatrix [
                              0.008159 0.000215 0.008131
                              3e-06 0 -1.7e-05
                            ]
                          }
                        }
                      }
                    ]
                    name "AR3"
                    boundingObject USE AR3
                    physics Physics {
                      density -1
                      mass 1.02
                      centerOfMass [
                        0 -0.085353 -9.9e-05
                      ]
                      inertiaMatrix [
                        0.012869 0.000621 0.012798
                        0 0 2.4e-05
                      ]
                    }
                  }
                }
              ]
              name "AR2"
              boundingObject USE AR2
              physics Physics {
                density -1
                mass 0.16
                centerOfMass [
                  0.003862 -0.037976 0
                ]
                inertiaMatrix [
                  0.000345 0.000177 0.000401
                  -8e-06 0 0
                ]
              }
            }
          }
        ]
        name "AR1"
        boundingObject USE AR1
        physics Physics {
          density -1
          mass 0.53
          centerOfMass [
            -0.000677 -0.044974 0
          ]
          inertiaMatrix [
            0.001293 0.000293 0.001367
            -1.7e-05 0 0
          ]
        }
      }
    }
    HingeJoint {
      jointParameters HingeJointParameters {
        position 9.255361536009852e-06
        axis 0 0 1
        anchor 0.0625 0 -0.1155
      }
      device [
        RotationalMotor {
          name "Waist"
          maxTorque 10000
        }
        PositionSensor {
          name "Waist_sensor"
        }
      ]
      endPoint Solid {
        translation 0.0625 0 -0.1155
        rotation 0 0 1 9.255384597355792e-06
        children [
          Shape {
            appearance DEF Waist_material PBRAppearance {
              baseColor 0.4 0.4 0.4
              roughness 1
              metalness 0
            }
            geometry DEF Waist Mesh {
              url [
                "./T1_release_meshes/Waist.STL"
              ]
            }
          }
          HingeJoint {
            jointParameters HingeJointParameters {
              position -0.293385000222278
              axis 0 1 0
              anchor 0 0.106 0
            }
            device [
              RotationalMotor {
                name "Left_Hip_Pitch"
                maxTorque 10000
              }
              PositionSensor {
                name "Left_Hip_Pitch_sensor"
              }
            ]
            endPoint Solid {
              translation 0 0.106 0
              rotation 0 -1 0 0.2933850002222778
              children [
                Shape {
                  appearance DEF Hip_Pitch_Left_material PBRAppearance {
                    baseColor 0.76 0.76 0.76
                    roughness 1
                    metalness 0
                  }
                  geometry DEF Hip_Pitch_Left Mesh {
                    url [
                      "./T1_release_meshes/Hip_Pitch_Left.STL"
                    ]
                  }
                }
                HingeJoint {
                  jointParameters HingeJointParameters {
                    position 0.0013431837415159872
                    anchor 0 0 -0.02
                  }
                  device [
                    RotationalMotor {
                      name "Left_Hip_Roll"
                      maxTorque 10000
                    }
                    PositionSensor {
                      name "Left_Hip_Roll_sensor"
                    }
                  ]
                  endPoint Solid {
                    translation 0 0 -0.02
                    rotation 1 0 0 0.0013431837415832752
                    children [
                      Shape {
                        appearance DEF Hip_Roll_Left_material PBRAppearance {
                          baseColor 0.4 0.4 0.4
                          roughness 1
                          metalness 0
                        }
                        geometry DEF Hip_Roll_Left Mesh {
                          url [
                            "./T1_release_meshes/Hip_Roll_Left.STL"
                          ]
                        }
                      }
                      HingeJoint {
                        jointParameters HingeJointParameters {
                          position -0.0006392841761652684
                          axis 0 0 1
                          anchor 0 0 -0.081854
                        }
                        device [
                          RotationalMotor {
                            name "Left_Hip_Yaw"
                            maxTorque 10000
                          }
                          PositionSensor {
                            name "Left_Hip_Yaw_sensor"
                          }
                        ]
                        endPoint Solid {
                          translation 0 0 -0.081854
                          rotation 0 0 -1 0.000639284176182883
                          children [
                            Shape {
                              appearance DEF Hip_Yaw_Left_material PBRAppearance {
                                baseColor 0.4 0.4 0.4
                                roughness 1
                                metalness 0
                              }
                              geometry DEF Hip_Yaw_Left Mesh {
                                url [
                                  "./T1_release_meshes/Hip_Yaw_Left.STL"
                                ]
                              }
                            }
                            HingeJoint {
                              jointParameters HingeJointParameters {
                                position 0.6212242295631947
                                axis 0 1 0
                                anchor -0.014 0 -0.134
                              }
                              device [
                                RotationalMotor {
                                  name "Left_Knee_Pitch"
                                  maxTorque 10000
                                }
                                PositionSensor {
                                  name "Left_Knee_Pitch_sensor"
                                }
                              ]
                              endPoint Solid {
                                translation -0.014 0 -0.134
                                rotation 0 1 0 0.621224229563195
                                children [
                                  Shape {
                                    appearance DEF Shank_Left_material PBRAppearance {
                                      baseColor 0.4 0.4 0.4
                                      roughness 1
                                      metalness 0
                                    }
                                    geometry DEF Shank_Left Mesh {
                                      url [
                                        "./T1_release_meshes/Shank_Left.STL"
                                      ]
                                    }
                                  }
                                  HingeJoint {
                                    jointParameters HingeJointParameters {
                                      position -0.30642889969153847
                                      axis 0 1 0
                                      anchor 0 0 -0.28
                                    }
                                    endPoint Solid {
                                      translation 0 0 -0.28
                                      rotation 0 -1 0 0.3064288996915384
                                      children [
                                        Shape {
                                          appearance DEF Ankle_Cross_Left_material PBRAppearance {
                                            baseColor 0.4 0.4 0.4
                                            roughness 1
                                            metalness 0
                                          }
                                          geometry DEF Ankle_Cross_Left Mesh {
                                            url [
                                              "./T1_release_meshes/Ankle_Cross_Left.STL"
                                            ]
                                          }
                                        }
                                        HingeJoint {
                                          jointParameters HingeJointParameters {
                                            position -0.0010544764684841113
                                            anchor 0 0.00025 -0.012
                                          }
                                          endPoint Solid {
                                            translation 0 0.00025 -0.012
                                            rotation -1 0 0 0.0010544764683214467
                                            children [
                                              HingeJoint {
                                                jointParameters HingeJointParameters {
                                                  position 0.32203870887869546
                                                  axis 0 1 0
                                                  anchor -0.0415 0.0275 0.0327
                                                  staticFriction 0.05
                                                }
                                                endPoint Solid {
                                                  translation -0.0415 0.0275 0.0327
                                                  rotation 0 1 0 0.3220387088786955
                                                  children [
                                                    HingeJoint {
                                                      jointParameters HingeJointParameters {
                                                        position 4.4691704767890934e-05
                                                        axis 0 0 1
                                                        staticFriction 0.05
                                                      }
                                                      endPoint SolidReference {
                                                        solidName "Up_Left_XX_Ball"
                                                      }
                                                    }
                                                  ]
                                                  physics Physics {
                                                    density -1
                                                    mass 0.005
                                                    centerOfMass [
                                                      0 0 0
                                                    ]
                                                    inertiaMatrix [
                                                      1e-05 1e-05 1e-05
                                                      0 0 0
                                                    ]
                                                  }
                                                }
                                              }
                                              HingeJoint {
                                                jointParameters HingeJointParameters {
                                                  position 0.3074209535491772
                                                  axis 0 1 0
                                                  anchor -0.0415 -0.0275 0.0327
                                                  staticFriction 0.05
                                                }
                                                endPoint Solid {
                                                  translation -0.0415 -0.0275 0.0327
                                                  rotation 0 1 0 0.3074209535491773
                                                  children [
                                                    HingeJoint {
                                                      jointParameters HingeJointParameters {
                                                        position 0.0011484688138699369
                                                        axis 0 0 1
                                                        staticFriction 0.05
                                                      }
                                                      endPoint SolidReference {
                                                        solidName "Down_Left_XX_Ball"
                                                      }
                                                    }
                                                  ]
                                                  name "solid(1)"
                                                  physics Physics {
                                                    density -1
                                                    mass 0.005
                                                    centerOfMass [
                                                      0 0 0
                                                    ]
                                                    inertiaMatrix [
                                                      1e-05 1e-05 1e-05
                                                      0 0 0
                                                    ]
                                                  }
                                                }
                                              }
                                              Shape {
                                                appearance DEF left_foot_link_material PBRAppearance {
                                                  baseColor 0.4 0.4 0.4
                                                  roughness 1
                                                  metalness 0
                                                }
                                                geometry DEF left_foot_link Mesh {
                                                  url [
                                                    "./T1_release_meshes/left_foot_link.STL"
                                                  ]
                                                }
                                              }
                                            ]
                                            name "left_foot_link"
                                            boundingObject Pose {
                                              translation 0.010384 0 -0.0155
                                              children [
                                                Box {
                                                  size 0.22487 0.1 0.031
                                                }
                                              ]
                                            }
                                            physics Physics {
                                              density -1
                                              mass 0.685
                                              centerOfMass [
                                                -0.000249 0 -0.00914
                                              ]
                                              inertiaMatrix [
                                                0.000738 0.002385 0.002671
                                                0 -0.000147 0
                                              ]
                                            }
                                          }
                                        }
                                      ]
                                      name "Ankle_Cross_Left"
                                      physics Physics {
                                        density -1
                                        mass 0.073
                                        centerOfMass [
                                          -0.003722 0 -0.007981
                                        ]
                                        inertiaMatrix [
                                          1.2e-05 2.9e-05 2.5e-05
                                          0 3e-06 0
                                        ]
                                      }
                                    }
                                  }
                                  HingeJoint {
                                    jointParameters HingeJointParameters {
                                      position 0.34305865027265414
                                      axis 0 1 0
                                      anchor -0.014 0.02775 -0.096
                                    }
                                    device [
                                      RotationalMotor {
                                        name "Crank_Up_Left"
                                        maxTorque 10000
                                      }
                                      PositionSensor {
                                        name "Crank_Up_Left_sensor"
                                      }
                                    ]
                                    endPoint Solid {
                                      translation -0.014 0.02775 -0.096
                                      rotation 0 1 0 0.34305865027265464
                                      children [
                                        Shape {
                                          appearance DEF Crank_Up_Left_material PBRAppearance {
                                            baseColor 0.752941 0.752941 0.752941
                                            roughness 1
                                            metalness 0
                                          }
                                          geometry DEF Crank_Up_Left Mesh {
                                            url [
                                              "./T1_release_meshes/Crank_Up_Left.STL"
                                            ]
                                          }
                                        }
                                        HingeJoint {
                                          jointParameters HingeJointParameters {
                                            position 9.1222319819357e-05
                                            anchor 0.042936 0 0.002347
                                          }
                                          endPoint Solid {
                                            translation 0.042936 0 0.002347
                                            rotation 1 0 0 9.12223189868272e-05
                                            children [
                                              Shape {
                                                appearance DEF Up_Left_X_Ball_material PBRAppearance {
                                                  baseColor 0.752941 0.752941 0.752941
                                                  roughness 1
                                                  metalness 0
                                                }
                                                geometry DEF Up_Left_X_Ball Mesh {
                                                  url [
                                                    "./T1_release_meshes/Up_Left_X_Ball.STL"
                                                  ]
                                                }
                                              }
                                              HingeJoint {
                                                jointParameters HingeJointParameters {
                                                  position -0.3274489241174704
                                                  axis 0 1 0
                                                }
                                                endPoint Solid {
                                                  rotation 0 -1 0 0.32744892411747073
                                                  children [
                                                    Shape {
                                                      appearance DEF Up_Left_Y_Ball_material PBRAppearance {
                                                        baseColor 0.752941 0.752941 0.752941
                                                        roughness 1
                                                        metalness 0
                                                      }
                                                      geometry DEF Up_Left_Y_Ball Mesh {
                                                        url [
                                                          "./T1_release_meshes/Up_Left_Y_Ball.STL"
                                                        ]
                                                      }
                                                    }
                                                    HingeJoint {
                                                      jointParameters HingeJointParameters {
                                                        position -0.0002597038068071651
                                                        axis 0 0 1
                                                      }
                                                      endPoint Solid {
                                                        rotation 0 0 -1 0.000259703807235272
                                                        children [
                                                          Shape {
                                                            appearance DEF Link_Long_Left_material PBRAppearance {
                                                              baseColor 0.752941 0.752941 0.752941
                                                              roughness 1
                                                              metalness 0
                                                            }
                                                            geometry DEF Link_Long_Left Mesh {
                                                              url [
                                                                "./T1_release_meshes/Link_Long_Left.STL"
                                                              ]
                                                            }
                                                          }
                                                          HingeJoint {
                                                            jointParameters HingeJointParameters {
                                                              position -0.0010866413121592953
                                                              anchor -0.070436 0 -0.16565
                                                            }
                                                            endPoint Solid {
                                                              translation -0.070436 0 -0.16565
                                                              rotation -1 0 0 0.0010866413122997095
                                                              children [
                                                                Shape {
                                                                  appearance DEF Up_Left_XX_Ball_material PBRAppearance {
                                                                    baseColor 0.752941 0.752941 0.752941
                                                                    roughness 1
                                                                    metalness 0
                                                                  }
                                                                  geometry DEF Up_Left_XX_Ball Mesh {
                                                                    url [
                                                                      "./T1_release_meshes/Up_Left_XX_Ball.STL"
                                                                    ]
                                                                  }
                                                                }
                                                              ]
                                                              name "Up_Left_XX_Ball"
                                                              physics Physics {
                                                                density -1
                                                                mass 0.001
                                                                centerOfMass [
                                                                  0 0 0
                                                                ]
                                                                inertiaMatrix [
                                                                  4.071504e-10 4.071504e-10 4.071504e-10
                                                                  -4.591775e-41 2.039158e-56 -2.295887e-41
                                                                ]
                                                              }
                                                            }
                                                          }
                                                        ]
                                                        name "Link_Long_Left"
                                                        physics Physics {
                                                          density -1
                                                          mass 0.057
                                                          centerOfMass [
                                                            -0.023162 0 -0.08712
                                                          ]
                                                          inertiaMatrix [
                                                            0.000632 0.000707 7.6e-05
                                                            0 0.000201 0
                                                          ]
                                                        }
                                                      }
                                                    }
                                                  ]
                                                  name "Up_Left_Y_Ball"
                                                  physics Physics {
                                                    density -1
                                                    mass 0.001
                                                    centerOfMass [
                                                      0 0 0
                                                    ]
                                                    inertiaMatrix [
                                                      4.071504e-10 4.071504e-10 4.071504e-10
                                                      0 -1.019579e-56 -2.295887e-41
                                                    ]
                                                  }
                                                }
                                              }
                                            ]
                                            name "Up_Left_X_Ball"
                                            physics Physics {
                                              density -1
                                              mass 0.001
                                              centerOfMass [
                                                0 0 0
                                              ]
                                              inertiaMatrix [
                                                4.071504e-10 4.071504e-10 4.071504e-10
                                                0 -1.019579e-56 -2.295887e-41
                                              ]
                                            }
                                          }
                                        }
                                      ]
                                      name "Crank_Up_Left"
                                      physics Physics {
                                        density -1
                                        mass 0.0395
                                        centerOfMass [
                                          0.015723 0.006606 0.000859
                                        ]
                                        inertiaMatrix [
                                          5e-06 2.9e-05 2.8e-05
                                          3e-06 1e-06 0
                                        ]
                                      }
                                    }
                                  }
                                  HingeJoint {
                                    jointParameters HingeJointParameters {
                                      position 0.3299236723945821
                                      axis 0 1 0
                                      anchor -0.014 -0.02725 -0.156
                                    }
                                    device [
                                      RotationalMotor {
                                        name "Crank_Down_Left"
                                        maxTorque 10000
                                      }
                                      PositionSensor {
                                        name "Crank_Down_Left_sensor"
                                      }
                                    ]
                                    endPoint Solid {
                                      translation -0.014 -0.02725 -0.156
                                      rotation 0 1 0 0.32992367239458226
                                      children [
                                        Shape {
                                          appearance DEF Crank_Down_Left_material PBRAppearance {
                                            baseColor 0.752941 0.752941 0.752941
                                            roughness 1
                                            metalness 0
                                          }
                                          geometry DEF Crank_Down_Left Mesh {
                                            url [
                                              "./T1_release_meshes/Crank_Down_Left.STL"
                                            ]
                                          }
                                        }
                                        HingeJoint {
                                          jointParameters HingeJointParameters {
                                            position 0.0010070994307272711
                                            anchor 0.042593 0 -0.005899
                                          }
                                          endPoint Solid {
                                            translation 0.042593 0 -0.005899
                                            rotation 1 0 0 0.0010070994307205033
                                            children [
                                              Shape {
                                                appearance DEF Down_Left_X_Ball_material PBRAppearance {
                                                  baseColor 0.752941 0.752941 0.752941
                                                  roughness 1
                                                  metalness 0
                                                }
                                                geometry DEF Down_Left_X_Ball Mesh {
                                                  url [
                                                    "./T1_release_meshes/Down_Left_X_Ball.STL"
                                                  ]
                                                }
                                              }
                                              HingeJoint {
                                                jointParameters HingeJointParameters {
                                                  position -0.32892961993509945
                                                  axis 0 1 0
                                                }
                                                endPoint Solid {
                                                  rotation 0 -1 0 0.32892961993509895
                                                  children [
                                                    Shape {
                                                      appearance DEF Down_Left_Y_Ball_material PBRAppearance {
                                                        baseColor 0.752941 0.752941 0.752941
                                                        roughness 1
                                                        metalness 0
                                                      }
                                                      geometry DEF Down_Left_Y_Ball Mesh {
                                                        url [
                                                          "./T1_release_meshes/Down_Left_Y_Ball.STL"
                                                        ]
                                                      }
                                                    }
                                                    HingeJoint {
                                                      jointParameters HingeJointParameters {
                                                        position 0.0011547137504975822
                                                        axis 0 0 1
                                                      }
                                                      endPoint Solid {
                                                        rotation 0 0 0.9999999999999999 0.0011547137505617453
                                                        children [
                                                          Shape {
                                                            appearance DEF Link_Short_Left_material PBRAppearance {
                                                              baseColor 0.752941 0.752941 0.752941
                                                              roughness 1
                                                              metalness 0
                                                            }
                                                            geometry DEF Link_Short_Left Mesh {
                                                              url [
                                                                "./T1_release_meshes/Link_Short_Left.STL"
                                                              ]
                                                            }
                                                          }
                                                          HingeJoint {
                                                            jointParameters HingeJointParameters {
                                                              position -0.0019581457670945213
                                                              anchor -0.070093 0 -0.097401
                                                            }
                                                            endPoint Solid {
                                                              translation -0.070093 0 -0.097401
                                                              rotation -1 0 0 0.001958145767061316
                                                              children [
                                                                Shape {
                                                                  appearance DEF Down_Left_XX_Ball_material PBRAppearance {
                                                                    baseColor 0.752941 0.752941 0.752941
                                                                    roughness 1
                                                                    metalness 0
                                                                  }
                                                                  geometry DEF Down_Left_XX_Ball Mesh {
                                                                    url [
                                                                      "./T1_release_meshes/Down_Left_XX_Ball.STL"
                                                                    ]
                                                                  }
                                                                }
                                                              ]
                                                              name "Down_Left_XX_Ball"
                                                              physics Physics {
                                                                density -1
                                                                mass 0.001
                                                                centerOfMass [
                                                                  0 0 0
                                                                ]
                                                                inertiaMatrix [
                                                                  4.071504e-10 4.071504e-10 4.071504e-10
                                                                  -4.591775e-41 2.039158e-56 -2.295887e-41
                                                                ]
                                                              }
                                                            }
                                                          }
                                                        ]
                                                        name "Link_Short_Left"
                                                        physics Physics {
                                                          density -1
                                                          mass 0.04
                                                          centerOfMass [
                                                            -0.031486 0 -0.050737
                                                          ]
                                                          inertiaMatrix [
                                                            0.000158 0.000229 7.1e-05
                                                            0 0.000104 0
                                                          ]
                                                        }
                                                      }
                                                    }
                                                  ]
                                                  name "Down_Left_Y_Ball"
                                                  physics Physics {
                                                    density -1
                                                    mass 0.001
                                                    centerOfMass [
                                                      0 0 0
                                                    ]
                                                    inertiaMatrix [
                                                      4.071504e-10 4.071504e-10 4.071504e-10
                                                      5.739719e-42 -6.372368e-58 -2.869859e-42
                                                    ]
                                                  }
                                                }
                                              }
                                            ]
                                            name "Down_Left_X_Ball"
                                            physics Physics {
                                              density -1
                                              mass 0.001
                                              centerOfMass [
                                                0 0 0
                                              ]
                                              inertiaMatrix [
                                                4.071504e-10 4.071504e-10 4.071504e-10
                                                5.739719e-42 -6.372368e-58 -2.869859e-42
                                              ]
                                            }
                                          }
                                        }
                                      ]
                                      name "Crank_Down_Left"
                                      physics Physics {
                                        density -1
                                        mass 0.0395
                                        centerOfMass [
                                          0.015597 -0.006606 -0.00216
                                        ]
                                        inertiaMatrix [
                                          5e-06 2.9e-05 2.8e-05
                                          -3e-06 -2e-06 0
                                        ]
                                      }
                                    }
                                  }
                                ]
                                name "Shank_Left"
                                boundingObject USE Shank_Left
                                physics Physics {
                                  density -1
                                  mass 1.62
                                  centerOfMass [
                                    -0.006695 0.000835 -0.119291
                                  ]
                                  inertiaMatrix [
                                    0.029609 0.029555 0.00172
                                    0 0.00148 3.2e-05
                                  ]
                                }
                              }
                            }
                          ]
                          name "Hip_Yaw_Left"
                          boundingObject USE Hip_Yaw_Left
                          physics Physics {
                            density -1
                            mass 2.166
                            centerOfMass [
                              -0.007233 0.000206 -0.089184
                            ]
                            inertiaMatrix [
                              0.025108 0.025733 0.002787
                              -7e-06 0.002094 -5e-05
                            ]
                          }
                        }
                      }
                    ]
                    name "Hip_Roll_Left"
                    boundingObject USE Hip_Roll_Left
                    physics Physics {
                      density -1
                      mass 0.385
                      centerOfMass [
                        0.001101 2.4e-05 -0.05375
                      ]
                      inertiaMatrix [
                        0.001517 0.001743 0.000515
                        0 1.7e-05 0
                      ]
                    }
                  }
                }
              ]
              name "Hip_Pitch_Left"
              boundingObject USE Hip_Pitch_Left
              physics Physics {
                density -1
                mass 1.021
                centerOfMass [
                  0.000534 -0.007296 -0.018083
                ]
                inertiaMatrix [
                  0.001805 0.001421 0.001292
                  6e-06 -1.5e-05 8e-05
                ]
              }
            }
          }
          HingeJoint {
            jointParameters HingeJointParameters {
              position -0.2997861426527688
              axis 0 1 0
              anchor 0 -0.106 0
            }
            device [
              RotationalMotor {
                name "Right_Hip_Pitch"
                maxTorque 10000
              }
              PositionSensor {
                name "Right_Hip_Pitch_sensor"
              }
            ]
            endPoint Solid {
              translation 0 -0.106 0
              rotation 0 -1 0 0.2997861426527685
              children [
                Shape {
                  appearance DEF Hip_Pitch_Right_material PBRAppearance {
                    baseColor 0.76 0.76 0.76
                    roughness 1
                    metalness 0
                  }
                  geometry DEF Hip_Pitch_Right Mesh {
                    url [
                      "./T1_release_meshes/Hip_Pitch_Right.STL"
                    ]
                  }
                }
                HingeJoint {
                  jointParameters HingeJointParameters {
                    position -0.0032297678374281556
                    anchor 0 0 -0.02
                  }
                  device [
                    RotationalMotor {
                      name "Right_Hip_Roll"
                      maxTorque 10000
                    }
                    PositionSensor {
                      name "Right_Hip_Roll_sensor"
                    }
                  ]
                  endPoint Solid {
                    translation 0 0 -0.02
                    rotation -1 0 0 0.003229767837391186
                    children [
                      Shape {
                        appearance DEF Hip_Roll_Right_material PBRAppearance {
                          baseColor 0.4 0.4 0.4
                          roughness 1
                          metalness 0
                        }
                        geometry DEF Hip_Roll_Right Mesh {
                          url [
                            "./T1_release_meshes/Hip_Roll_Right.STL"
                          ]
                        }
                      }
                      HingeJoint {
                        jointParameters HingeJointParameters {
                          position -0.005729115208252586
                          axis 0 0 1
                          anchor 0 0 -0.081854
                        }
                        device [
                          RotationalMotor {
                            name "Right_Hip_Yaw"
                            maxTorque 10000
                          }
                          PositionSensor {
                            name "Right_Hip_Yaw_sensor"
                          }
                        ]
                        endPoint Solid {
                          translation 0 0 -0.081854
                          rotation 0 0 -1 0.005729115208237714
                          children [
                            Shape {
                              appearance DEF Hip_Yaw_Right_material PBRAppearance {
                                baseColor 0.4 0.4 0.4
                                roughness 1
                                metalness 0
                              }
                              geometry DEF Hip_Yaw_Right Mesh {
                                url [
                                  "./T1_release_meshes/Hip_Yaw_Right.STL"
                                ]
                              }
                            }
                            HingeJoint {
                              jointParameters HingeJointParameters {
                                position 0.6228235511860807
                                axis 0 1 0
                                anchor -0.014 0 -0.134
                              }
                              device [
                                RotationalMotor {
                                  name "Right_Knee_Pitch"
                                  maxTorque 10000
                                }
                                PositionSensor {
                                  name "Right_Knee_Pitch_sensor"
                                }
                              ]
                              endPoint Solid {
                                translation -0.014 0 -0.134
                                rotation 0 1 0 0.6228235511860806
                                children [
                                  Shape {
                                    appearance DEF Shank_Right_material PBRAppearance {
                                      baseColor 0.4 0.4 0.4
                                      roughness 1
                                      metalness 0
                                    }
                                    geometry DEF Shank_Right Mesh {
                                      url [
                                        "./T1_release_meshes/Shank_Right.STL"
                                      ]
                                    }
                                  }
                                  HingeJoint {
                                    jointParameters HingeJointParameters {
                                      position -0.3020814547668102
                                      axis 0 1 0
                                      anchor 0 0 -0.28
                                    }
                                    endPoint Solid {
                                      translation 0 0 -0.28
                                      rotation 0 -1 0 0.3020814547668108
                                      children [
                                        Shape {
                                          appearance DEF Ankle_Cross_Right_material PBRAppearance {
                                            baseColor 0.4 0.4 0.4
                                            roughness 1
                                            metalness 0
                                          }
                                          geometry DEF Ankle_Cross_Right Mesh {
                                            url [
                                              "./T1_release_meshes/Ankle_Cross_Right.STL"
                                            ]
                                          }
                                        }
                                        HingeJoint {
                                          jointParameters HingeJointParameters {
                                            position 0.0011773952646259062
                                            anchor 0 -0.00025 -0.012
                                          }
                                          endPoint Solid {
                                            translation 0 -0.00025 -0.012
                                            rotation 1 0 0 0.0011773952647237292
                                            children [
                                              HingeJoint {
                                                jointParameters HingeJointParameters {
                                                  position 0.30362611684516283
                                                  axis 0 1 0
                                                  anchor -0.0415 0.0275 0.0327
                                                  staticFriction 0.05
                                                }
                                                endPoint Solid {
                                                  translation -0.0415 0.0275 0.0327
                                                  rotation 0 1 0 0.3036261168451633
                                                  children [
                                                    HingeJoint {
                                                      jointParameters HingeJointParameters {
                                                        position 0.0007928232595042192
                                                        axis 0 0 1
                                                        staticFriction 0.05
                                                      }
                                                      endPoint SolidReference {
                                                        solidName "Down_Right_XX_Ball"
                                                      }
                                                    }
                                                  ]
                                                  physics Physics {
                                                    density -1
                                                    mass 0.005
                                                    centerOfMass [
                                                      0 0 0
                                                    ]
                                                    inertiaMatrix [
                                                      1e-05 1e-05 1e-05
                                                      0 0 0
                                                    ]
                                                  }
                                                }
                                              }
                                              HingeJoint {
                                                jointParameters HingeJointParameters {
                                                  position 0.31784639827173095
                                                  axis 0 1 0
                                                  anchor -0.0415 -0.0275 0.0327
                                                  staticFriction 0.05
                                                }
                                                endPoint Solid {
                                                  translation -0.0415 -0.0275 0.0327
                                                  rotation 0 0.9999999999999999 0 0.31784639827173145
                                                  children [
                                                    HingeJoint {
                                                      jointParameters HingeJointParameters {
                                                        position 0.0017865181557223681
                                                        axis 0 0 1
                                                        staticFriction 0.05
                                                      }
                                                      endPoint SolidReference {
                                                        solidName "Up_Right_XX_Ball"
                                                      }
                                                    }
                                                  ]
                                                  name "solid(1)"
                                                  physics Physics {
                                                    density -1
                                                    mass 0.005
                                                    centerOfMass [
                                                      0 0 0
                                                    ]
                                                    inertiaMatrix [
                                                      1e-05 1e-05 1e-05
                                                      0 0 0
                                                    ]
                                                  }
                                                }
                                              }
                                              Shape {
                                                appearance DEF right_foot_link_material PBRAppearance {
                                                  baseColor 0.4 0.4 0.4
                                                  roughness 1
                                                  metalness 0
                                                }
                                                geometry DEF right_foot_link Mesh {
                                                  url [
                                                    "./T1_release_meshes/right_foot_link.STL"
                                                  ]
                                                }
                                              }
                                            ]
                                            name "right_foot_link"
                                            boundingObject Pose {
                                              translation 0.010384 0 -0.0155
                                              children [
                                                Box {
                                                  size 0.22487 0.1 0.031
                                                }
                                              ]
                                            }
                                            physics Physics {
                                              density -1
                                              mass 0.685
                                              centerOfMass [
                                                -0.000248 0 -0.00914
                                              ]
                                              inertiaMatrix [
                                                0.000738 0.002385 0.002671
                                                0 -0.000147 0
                                              ]
                                            }
                                          }
                                        }
                                      ]
                                      name "Ankle_Cross_Right"
                                      physics Physics {
                                        density -1
                                        mass 0.073
                                        centerOfMass [
                                          -0.003722 0 -0.007981
                                        ]
                                        inertiaMatrix [
                                          1.2e-05 2.9e-05 2.5e-05
                                          0 3e-06 0
                                        ]
                                      }
                                    }
                                  }
                                  HingeJoint {
                                    jointParameters HingeJointParameters {
                                      position 0.33917301483331863
                                      axis 0 1 0
                                      anchor -0.014 -0.02775 -0.096
                                    }
                                    device [
                                      RotationalMotor {
                                        name "Crank_Up_Right"
                                        maxTorque 10000
                                      }
                                      PositionSensor {
                                        name "Crank_Up_Right_sensor"
                                      }
                                    ]
                                    endPoint Solid {
                                      translation -0.014 -0.02775 -0.096
                                      rotation 0 0.9999999999999999 0 0.339173014833319
                                      children [
                                        Shape {
                                          appearance DEF Crank_Up_Right_material PBRAppearance {
                                            baseColor 0.752941 0.752941 0.752941
                                            roughness 1
                                            metalness 0
                                          }
                                          geometry DEF Crank_Up_Right Mesh {
                                            url [
                                              "./T1_release_meshes/Crank_Up_Right.STL"
                                            ]
                                          }
                                        }
                                        HingeJoint {
                                          jointParameters HingeJointParameters {
                                            position 0.0007198238520880225
                                            anchor 0.042936 0 0.002347
                                          }
                                          endPoint Solid {
                                            translation 0.042936 0 0.002347
                                            rotation 0.9999999999999999 0 0 0.0007198238518024793
                                            children [
                                              Shape {
                                                appearance DEF Up_Right_X_Ball_material PBRAppearance {
                                                  baseColor 0.752941 0.752941 0.752941
                                                  roughness 1
                                                  metalness 0
                                                }
                                                geometry DEF Up_Right_X_Ball Mesh {
                                                  url [
                                                    "./T1_release_meshes/Up_Right_X_Ball.STL"
                                                  ]
                                                }
                                              }
                                              HingeJoint {
                                                jointParameters HingeJointParameters {
                                                  position -0.3234087054733607
                                                  axis 0 1 0
                                                }
                                                endPoint Solid {
                                                  rotation 0 -1 0 0.32340870547336026
                                                  children [
                                                    Shape {
                                                      appearance DEF Up_Right_Y_Ball_material PBRAppearance {
                                                        baseColor 0.752941 0.752941 0.752941
                                                        roughness 1
                                                        metalness 0
                                                      }
                                                      geometry DEF Up_Right_Y_Ball Mesh {
                                                        url [
                                                          "./T1_release_meshes/Up_Right_Y_Ball.STL"
                                                        ]
                                                      }
                                                    }
                                                    HingeJoint {
                                                      jointParameters HingeJointParameters {
                                                        position 0.0023831192601499757
                                                        axis 0 0 1
                                                      }
                                                      endPoint Solid {
                                                        rotation 0 0 1 0.0023831192601209803
                                                        children [
                                                          Shape {
                                                            appearance DEF Link_Long_Right_material PBRAppearance {
                                                              baseColor 0.752941 0.752941 0.752941
                                                              roughness 1
                                                              metalness 0
                                                            }
                                                            geometry DEF Link_Long_Right Mesh {
                                                              url [
                                                                "./T1_release_meshes/Link_Long_Right.STL"
                                                              ]
                                                            }
                                                          }
                                                          HingeJoint {
                                                            jointParameters HingeJointParameters {
                                                              position 0.00043595047585686937
                                                              anchor -0.070436 0 -0.16565
                                                            }
                                                            endPoint Solid {
                                                              translation -0.070436 0 -0.16565
                                                              rotation 0.9999999999999999 0 0 0.0004359504763067071
                                                              children [
                                                                Shape {
                                                                  appearance DEF Up_Right_XX_Ball_material PBRAppearance {
                                                                    baseColor 0.752941 0.752941 0.752941
                                                                    roughness 1
                                                                    metalness 0
                                                                  }
                                                                  geometry DEF Up_Right_XX_Ball Mesh {
                                                                    url [
                                                                      "./T1_release_meshes/Up_Right_XX_Ball.STL"
                                                                    ]
                                                                  }
                                                                }
                                                              ]
                                                              name "Up_Right_XX_Ball"
                                                              physics Physics {
                                                                density -1
                                                                mass 0.001
                                                                centerOfMass [
                                                                  0 0 0
                                                                ]
                                                                inertiaMatrix [
                                                                  4.071504e-10 4.071504e-10 4.071504e-10
                                                                  -4.591775e-41 2.039158e-56 -2.295887e-41
                                                                ]
                                                              }
                                                            }
                                                          }
                                                        ]
                                                        name "Link_Long_Right"
                                                        physics Physics {
                                                          density -1
                                                          mass 0.0565
                                                          centerOfMass [
                                                            -0.023162 0 -0.08712
                                                          ]
                                                          inertiaMatrix [
                                                            0.000632 0.000707 7.6e-05
                                                            0 0.000201 0
                                                          ]
                                                        }
                                                      }
                                                    }
                                                  ]
                                                  name "Up_Right_Y_Ball"
                                                  physics Physics {
                                                    density -1
                                                    mass 0.001
                                                    centerOfMass [
                                                      0 0 0
                                                    ]
                                                    inertiaMatrix [
                                                      4.071504e-10 4.071504e-10 4.071504e-10
                                                      0 -1.019579e-56 -2.295887e-41
                                                    ]
                                                  }
                                                }
                                              }
                                            ]
                                            name "Up_Right_X_Ball"
                                            physics Physics {
                                              density -1
                                              mass 0.001
                                              centerOfMass [
                                                0 0 0
                                              ]
                                              inertiaMatrix [
                                                4.071504e-10 4.071504e-10 4.071504e-10
                                                0 -1.019579e-56 -2.295887e-41
                                              ]
                                            }
                                          }
                                        }
                                      ]
                                      name "Crank_Up_Right"
                                      physics Physics {
                                        density -1
                                        mass 0.04
                                        centerOfMass [
                                          0.015723 -0.006606 0.000859
                                        ]
                                        inertiaMatrix [
                                          5e-06 2.9e-05 2.8e-05
                                          -3e-06 1e-06 0
                                        ]
                                      }
                                    }
                                  }
                                  HingeJoint {
                                    jointParameters HingeJointParameters {
                                      position 0.3262332145735047
                                      axis 0 1 0
                                      anchor -0.014 0.02725 -0.156
                                    }
                                    device [
                                      RotationalMotor {
                                        name "Crank_Down_Right"
                                        maxTorque 10000
                                      }
                                      PositionSensor {
                                        name "Crank_Down_Right_sensor"
                                      }
                                    ]
                                    endPoint Solid {
                                      translation -0.014 0.02725 -0.156
                                      rotation 0 1 0 0.3262332145735043
                                      children [
                                        Shape {
                                          appearance DEF Crank_Down_Right_material PBRAppearance {
                                            baseColor 0.752941 0.752941 0.752941
                                            roughness 1
                                            metalness 0
                                          }
                                          geometry DEF Crank_Down_Right Mesh {
                                            url [
                                              "./T1_release_meshes/Crank_Down_Right.STL"
                                            ]
                                          }
                                        }
                                        HingeJoint {
                                          jointParameters HingeJointParameters {
                                            position 0.00044965070734997287
                                            anchor 0.042593 0 -0.005899
                                          }
                                          endPoint Solid {
                                            translation 0.042593 0 -0.005899
                                            rotation 1 0 0 0.00044965070751128665
                                            children [
                                              Shape {
                                                appearance DEF Down_Right_X_Ball_material PBRAppearance {
                                                  baseColor 0.752941 0.752941 0.752941
                                                  roughness 1
                                                  metalness 0
                                                }
                                                geometry DEF Down_Right_X_Ball Mesh {
                                                  url [
                                                    "./T1_release_meshes/Down_Right_X_Ball.STL"
                                                  ]
                                                }
                                              }
                                              HingeJoint {
                                                jointParameters HingeJointParameters {
                                                  position -0.3246890953947149
                                                  axis 0 1 0
                                                }
                                                endPoint Solid {
                                                  rotation 0 -1 0 0.3246890953947154
                                                  children [
                                                    Shape {
                                                      appearance DEF Down_Right_Y_Ball_material PBRAppearance {
                                                        baseColor 0.752941 0.752941 0.752941
                                                        roughness 1
                                                        metalness 0
                                                      }
                                                      geometry DEF Down_Right_Y_Ball Mesh {
                                                        url [
                                                          "./T1_release_meshes/Down_Right_Y_Ball.STL"
                                                        ]
                                                      }
                                                    }
                                                    HingeJoint {
                                                      jointParameters HingeJointParameters {
                                                        position 0.0012881678442878016
                                                        axis 0 0 1
                                                      }
                                                      endPoint Solid {
                                                        rotation 0 0 1 0.001288167844279481
                                                        children [
                                                          Shape {
                                                            appearance DEF Link_Short_Right_material PBRAppearance {
                                                              baseColor 0.752941 0.752941 0.752941
                                                              roughness 1
                                                              metalness 0
                                                            }
                                                            geometry DEF Link_Short_Right Mesh {
                                                              url [
                                                                "./T1_release_meshes/Link_Short_Right.STL"
                                                              ]
                                                            }
                                                          }
                                                          HingeJoint {
                                                            jointParameters HingeJointParameters {
                                                              position 0.0006974177536725661
                                                              anchor -0.070093 0 -0.097401
                                                            }
                                                            endPoint Solid {
                                                              translation -0.070093 0 -0.097401
                                                              rotation 1 0 0 0.0006974177536467371
                                                              children [
                                                                Shape {
                                                                  appearance DEF Down_Right_XX_Ball_material PBRAppearance {
                                                                    baseColor 0.752941 0.752941 0.752941
                                                                    roughness 1
                                                                    metalness 0
                                                                  }
                                                                  geometry DEF Down_Right_XX_Ball Mesh {
                                                                    url [
                                                                      "./T1_release_meshes/Down_Right_XX_Ball.STL"
                                                                    ]
                                                                  }
                                                                }
                                                              ]
                                                              name "Down_Right_XX_Ball"
                                                              physics Physics {
                                                                density -1
                                                                mass 0.001
                                                                centerOfMass [
                                                                  0 0 0
                                                                ]
                                                                inertiaMatrix [
                                                                  4.071504e-10 4.071504e-10 4.071504e-10
                                                                  -4.591775e-41 2.039158e-56 -2.295887e-41
                                                                ]
                                                              }
                                                            }
                                                          }
                                                        ]
                                                        name "Link_Short_Right"
                                                        physics Physics {
                                                          density -1
                                                          mass 0.04
                                                          centerOfMass [
                                                            -0.031486 0 -0.050737
                                                          ]
                                                          inertiaMatrix [
                                                            0.000158 0.000229 7.1e-05
                                                            0 0.000104 0
                                                          ]
                                                        }
                                                      }
                                                    }
                                                  ]
                                                  name "Down_Right_Y_Ball"
                                                  physics Physics {
                                                    density -1
                                                    mass 0.001
                                                    centerOfMass [
                                                      0 0 0
                                                    ]
                                                    inertiaMatrix [
                                                      4.071504e-10 4.071504e-10 4.071504e-10
                                                      5.739719e-42 -6.372368e-58 -2.869859e-42
                                                    ]
                                                  }
                                                }
                                              }
                                            ]
                                            name "Down_Right_X_Ball"
                                            physics Physics {
                                              density -1
                                              mass 0.001
                                              centerOfMass [
                                                0 0 0
                                              ]
                                              inertiaMatrix [
                                                4.071504e-10 4.071504e-10 4.071504e-10
                                                5.739719e-42 -6.372368e-58 -2.869859e-42
                                              ]
                                            }
                                          }
                                        }
                                      ]
                                      name "Crank_Down_Right"
                                      physics Physics {
                                        density -1
                                        mass 0.04
                                        centerOfMass [
                                          0.015597 0.006606 -0.00216
                                        ]
                                        inertiaMatrix [
                                          5e-06 2.9e-05 2.8e-05
                                          3e-06 -3e-06 0
                                        ]
                                      }
                                    }
                                  }
                                ]
                                name "Shank_Right"
                                boundingObject USE Shank_Right
                                physics Physics {
                                  density -1
                                  mass 1.62
                                  centerOfMass [
                                    -0.006574 -0.000315 -0.118161
                                  ]
                                  inertiaMatrix [
                                    0.029681 0.029596 0.001763
                                    4e-06 0.001479 -5e-05
                                  ]
                                }
                              }
                            }
                          ]
                          name "Hip_Yaw_Right"
                          boundingObject USE Hip_Yaw_Right
                          physics Physics {
                            density -1
                            mass 2.17
                            centerOfMass [
                              -0.007191 -0.000149 -0.08922
                            ]
                            inertiaMatrix [
                              0.025137 0.025762 0.002787
                              6e-06 0.002086 4.4e-05
                            ]
                          }
                        }
                      }
                    ]
                    name "Hip_Roll_Right"
                    boundingObject USE Hip_Roll_Right
                    physics Physics {
                      density -1
                      mass 0.385
                      centerOfMass [
                        0.001099 2.4e-05 -0.053748
                      ]
                      inertiaMatrix [
                        0.001517 0.001743 0.000515
                        0 1.7e-05 0
                      ]
                    }
                  }
                }
              ]
              name "Hip_Pitch_Right"
              boundingObject USE Hip_Pitch_Right
              physics Physics {
                density -1
                mass 1.021
                centerOfMass [
                  0.000534 0.007514 -0.018082
                ]
                inertiaMatrix [
                  0.001805 0.001421 0.001292
                  -8e-06 -1.5e-05 -8.5e-05
                ]
              }
            }
          }
        ]
        name "Waist"
        boundingObject USE Waist
        physics Physics {
          density -1
          mass 2.581
          centerOfMass [
            0.002284 3e-06 0.007301
          ]
          inertiaMatrix [
            0.005289 0.005299 0.004821
            0 0.000207 1e-06
          ]
        }
      }
    }
  ]
  name "T1_release"
  boundingObject USE Trunk
  physics Physics {
    density -1
    mass 11.7
    centerOfMass [
      0.055137 -1e-06 0.105062
    ]
    inertiaMatrix [
      0.09152872 0.07677872 0.05561711
      -4.253697e-07 0.0006463604 5.8234e-07
    ]
  }
  controller "<extern>"
  supervisor TRUE
}
Robot {
  name "camera_robot"
  controller "camera_publisher"
  supervisor TRUE
  children [
    Camera {
      translation 0 0 0
      name "rgb_cam"
      width 640
      height 480
      fieldOfView 1.2217
    }
    RangeFinder {
      translation 0 0 0
      name "depth_cam"
      width 640
      height 480
      fieldOfView 1.2217
      maxRange 10
    }
  ]
}
DEF origin Pose {
  children [
    Shape {
      appearance PBRAppearance {
        baseColor 0.937255 0.160784 0.160784
      }
      geometry Box {
        size 0.03 0.03 0.03
      }
    }
  ]
}
